<?xml version="1.0" ?>
<!-- =================================================================================== -->
<!-- |    This document was autogenerated by xacro from /home/dipz/robot_proj/bocbot_ws/src/bocbot/urdf/bocbot.urdf.xacro | -->
<!-- |    EDITING THIS FILE BY HAND IS NOT RECOMMENDED                                 | -->
<!-- =================================================================================== -->
<robot name="bocbot">
  <!-- Hexapedal Rocker-Bogie Plugin Configuration -->
  <gazebo>
    <plugin filename="libgazebo_ros_diff_drive.so" name="skid_steer_drive_controller">
      <ros>
        <namespace>/bocbot</namespace>
        <remapping>~/cmd_vel:=cmd_vel</remapping>
        <remapping>~/odom:=odom</remapping>
      </ros>
      <update_rate>100.0</update_rate>
      <!-- We have 3 pairs of wheels now! -->
      <num_wheel_pairs>3</num_wheel_pairs>
      <odometry_frame>odom</odometry_frame>
      <!-- Left Wheels -->
      <left_joint>front_left_wheel_joint</left_joint>
      <left_joint>mid_left_wheel_joint</left_joint>
      <left_joint>back_left_wheel_joint</left_joint>
      <!-- Right Wheels -->
      <right_joint>front_right_wheel_joint</right_joint>
      <right_joint>mid_right_wheel_joint</right_joint>
      <right_joint>back_right_wheel_joint</right_joint>
      <!-- Distances adjusted to match new geometry (y offsets) -->
      <wheel_separation>1.14</wheel_separation>
      <wheel_diameter>0.45</wheel_diameter>
      <robot_base_frame>robot_footprint</robot_base_frame>
      <max_wheel_torque>50</max_wheel_torque>
      <publish_odom>true</publish_odom>
      <publish_odom_tf>true</publish_odom_tf>
      <publish_wheel_tf>true</publish_wheel_tf>
      <odometry_source>world</odometry_source>
    </plugin>
  </gazebo>
  <!-- camera -->
  <gazebo reference="camera">
    <sensor name="camera_sensor" type="camera">
      <update_rate>30.0</update_rate>
      <always_on>1</always_on>
      <camera name="camera">
        <horizontal_fov>1.3962634</horizontal_fov>
        <image>
          <width>800</width>
          <height>800</height>
          <format>R8G8B8</format>
        </image>
        <clip>
          <near>0.02</near>
          <far>300</far>
        </clip>
        <distortion>
          <k1>0.0</k1>
          <k2>0.0</k2>
          <k3>0.0</k3>
          <p1>0.0</p1>
          <p2>0.0</p2>
          <center>0.5 0.5</center>
        </distortion>
      </camera>
      <plugin filename="libgazebo_ros_camera.so" name="camera_controller">
        <ros>
          <namespace>/bocbot</namespace>
          <argument>camera/image_raw:=/bocbot/camera/image</argument>
          <argument>camera/camera_info:=/bocbot/camera/image/camera_info</argument>
        </ros>
        <camera_name>camera</camera_name>
        <frame_name>camera</frame_name>
        <hack_baseline>0.21</hack_baseline>
      </plugin>
    </sensor>
  </gazebo>
  <!-- hokuyo -->
  <gazebo reference="hokuyo">
    <sensor name="head_hokuyo_sensor" type="ray">
      <pose>0 0 0 0 0 0</pose>
      <visualize>false</visualize>
      <update_rate>40</update_rate>
      <ray>
        <scan>
          <horizontal>
            <samples>720</samples>
            <resolution>1</resolution>
            <min_angle>-1.570796</min_angle>
            <max_angle>1.570796</max_angle>
          </horizontal>
        </scan>
        <range>
          <min>0.10</min>
          <max>30.0</max>
          <resolution>0.01</resolution>
        </range>
        <noise>
          <type>gaussian</type>
          <mean>0.0</mean>
          <stddev>0.01</stddev>
        </noise>
      </ray>
      <plugin filename="libgazebo_ros_ray_sensor.so" name="gazebo_ros_head_hokuyo_controller">
        <ros>
          <namespace>/bocbot</namespace>
          <argument>~/out:=scan</argument>
        </ros>
        <output_type>sensor_msgs/LaserScan</output_type>
      </plugin>
    </sensor>
  </gazebo>
  <!-- IMU -->
  <gazebo reference="imu_link">
    <gravity>true</gravity>
    <sensor name="imu_sensor" type="imu">
      <always_on>true</always_on>
      <update_rate>100</update_rate>
      <visualize>true</visualize>
      <plugin filename="libgazebo_ros_imu_sensor.so" name="imu_plugin">
        <ros>
          <namespace>/bocbot</namespace>
          <remapping>~/out:=imu</remapping>
        </ros>
        <initial_orientation_as_reference>false</initial_orientation_as_reference>
      </plugin>
    </sensor>
  </gazebo>
  <!-- ======================================================== -->
  <!-- ROBOTIC MECHANICS & KINEMATICS UPGRADE                   -->
  <!-- ======================================================== -->
  <link name="robot_footprint"/>
  <joint name="robot_footprint_joint" type="fixed">
    <origin rpy="0 0 0" xyz="0.0 0.0 0.45"/>
    <parent link="robot_footprint"/>
    <child link="base_link"/>
  </joint>
  <!-- Main Chassis -->
  <link name="base_link">
    <inertial>
      <mass value="4.0"/>
      <!-- ADVANCED MECHANICS: Lowering the Center of Mass (CoM). 
           By shifting the Z origin of the inertia down by 5cm (-0.05), 
           we simulate a heavy battery pack mounted at the very bottom 
           of the hull. This mathematically increases the tip-over angle,
           making it exceptionally stable on steep stairs. -->
      <origin rpy=" 0 0 0" xyz="0.0 0.0 -0.15"/>
      <inertia ixx="0.05" ixy="0" ixz="0" iyy="0.05" iyz="0" izz="0.05"/>
    </inertial>
    <collision name="collision">
      <origin rpy=" 0 0 0" xyz="0.0 0.0 0.0"/>
      <geometry>
        <box size="0.84 0.54 0.3"/>
      </geometry>
    </collision>
    <visual name="chassis_visual">
      <origin rpy=" 0 0 0" xyz="0.0 0.0 0.0"/>
      <geometry>
        <box size="0.9 0.6 0.36"/>
      </geometry>
    </visual>
  </link>
  <gazebo reference="base_link">
    <material>Gazebo/Green</material>
  </gazebo>
  <!-- IMU Sensor Link (New System Component) -->
  <link name="imu_link">
    <inertial>
      <mass value="0.001"/>
      <origin rpy="0 0 0" xyz="0.0 0.0 0.0"/>
      <inertia ixx="1e-6" ixy="0" ixz="0" iyy="1e-6" iyz="0" izz="1e-6"/>
    </inertial>
  </link>
  <joint name="imu_joint" type="fixed">
    <origin rpy="0 0 0" xyz="0.0 0.0 0.0"/>
    <parent link="base_link"/>
    <child link="imu_link"/>
  </joint>
  <!-- Camera -->
  <link name="camera">
    <visual name="camera_visual">
      <origin rpy="0 0 0" xyz="0.0 0.0 0.0"/>
      <geometry>
        <box size="0.09 0.15 0.09"/>
      </geometry>
    </visual>
  </link>
  <joint name="camera_joint" type="fixed">
    <origin rpy="0 0 0" xyz="0.45 0.0 0.0"/>
    <child link="camera"/>
    <parent link="base_link"/>
  </joint>
  <gazebo reference="camera">
    <material>Gazebo/Black</material>
  </gazebo>
  <!-- Hokuyo LiDAR -->
  <link name="hokuyo">
    <visual name="hokuyo_visual">
      <origin rpy="0 0 0" xyz="0.0 0.0 0.0"/>
      <geometry>
        <cylinder length="0.04" radius="0.03"/>
      </geometry>
    </visual>
  </link>
  <joint name="hokuyo_joint" type="fixed">
    <origin rpy="0 0 0" xyz="0.3 0.0 0.18"/>
    <child link="hokuyo"/>
    <parent link="base_link"/>
  </joint>
  <gazebo reference="hokuyo">
    <material>Gazebo/Black</material>
  </gazebo>
  <!-- ======================================================== -->
  <!-- MACROS FOR CLEAN CODE (Professional Robotics Standard)   -->
  <!-- ======================================================== -->
  <!-- =============================== -->
  <!-- LEFT SIDE ASSEMBLY              -->
  <!-- =============================== -->
  <link name="left_rocker_arm">
    <inertial>
      <mass value="0.5"/>
      <origin rpy="0 0 0" xyz="0.15 0.0 0.0"/>
      <inertia ixx="0.005" ixy="0" ixz="0" iyy="0.005" iyz="0" izz="0.005"/>
    </inertial>
    <visual>
      <origin rpy="0 0 0" xyz="0.15 0.0 0.0"/>
      <geometry>
        <box size="1.02 0.12 0.12"/>
      </geometry>
    </visual>
    <visual>
      <origin rpy="0 0 0" xyz="0.6 0.0 -0.15"/>
      <geometry>
        <box size="0.12 0.12 0.3"/>
      </geometry>
    </visual>
    <visual>
      <origin rpy="0 0 0" xyz="-0.3 0.0 -0.075"/>
      <geometry>
        <box size="0.12 0.12 0.15"/>
      </geometry>
    </visual>
    <collision>
      <origin rpy="0 0 0" xyz="0.15 0.0 -0.075"/>
      <geometry>
        <box size="0.9 0.06 0.15"/>
      </geometry>
    </collision>
  </link>
  <gazebo reference="left_rocker_arm">
    <material>Gazebo/DarkGrey</material>
  </gazebo>
  <joint name="left_differential_axle" type="revolute">
    <origin rpy="0 0 0" xyz="0.0 0.39 0.0"/>
    <parent link="base_link"/>
    <child link="left_rocker_arm"/>
    <axis xyz="0.0 3.0 0.0"/>
    <!-- ADVANCED MECHANICS: Mechanical Hard Stops.
         Changed from continuous back to revolute, but with strictly tuned limits 
         (+/- 0.6 radians). This simulates the physical chassis bumping against 
         the arm, preventing the robot from doing a full backflip over its own wheels. -->
    <limit effort="1000" lower="-0.6" upper="0.6" velocity="10"/>
    <dynamics damping="8.0" friction="2.0"/>
  </joint>
  <link name="front_left_wheel">
    <inertial>
      <mass value="0.8"/>
      <origin rpy="1.5707 0 0" xyz="0.0 0.0 0.0"/>
      <inertia ixx="0.0013" ixy="0" ixz="0" iyy="0.0013" iyz="0" izz="0.0022"/>
    </inertial>
    <visual>
      <origin rpy="1.5707 0 0" xyz="0.0 0.0 0.0"/>
      <geometry>
        <cylinder length="0.05" radius="0.075"/>
      </geometry>
    </visual>
    <collision>
      <origin rpy="1.5707 0 0" xyz="0.0 0.0 0.0"/>
      <geometry>
        <cylinder length="0.05" radius="0.075"/>
      </geometry>
    </collision>
  </link>
  <gazebo reference="front_left_wheel">
    <material>Gazebo/Grey</material>
    <!-- ADVANCED MECHANICS: Anisotropic Friction.
           In a 6-wheel skid steer, the wheels MUST slip sideways to turn.
           mu1 (forward friction) is high (1.2) for stair climbing grip.
           mu2 (lateral friction) is extremely low (0.1) so the robot
           can easily rotate on its center axis without fighting itself! -->
    <mu1>1.2</mu1>
    <mu2>0.1</mu2>
    <kp>1000000.0</kp>
    <kd>100.0</kd>
    <minDepth>0.001</minDepth>
  </gazebo>
  <joint name="front_left_wheel_joint" type="continuous">
    <origin rpy="0 0 0" xyz="1.8 0.54 -0.9"/>
    <parent link="left_rocker_arm"/>
    <child link="front_left_wheel"/>
    <axis xyz="0.0 3.0 0.0"/>
    <limit effort="100" velocity="20"/>
    <dynamics damping="0.1" friction="0.1"/>
  </joint>
  <link name="left_bogie_link">
    <inertial>
      <mass value="0.5"/>
      <origin rpy="0 0 0" xyz="0.0 0.0 0.0"/>
      <inertia ixx="0.005" ixy="0" ixz="0" iyy="0.005" iyz="0" izz="0.005"/>
    </inertial>
    <visual>
      <origin rpy="0 0 0" xyz="0.0 0.0 0.0"/>
      <geometry>
        <box size="0.72 0.12 0.12"/>
      </geometry>
    </visual>
    <visual>
      <origin rpy="0 0 0" xyz="0.3 0.0 -0.075"/>
      <geometry>
        <box size="0.12 0.12 0.15"/>
      </geometry>
    </visual>
    <visual>
      <origin rpy="0 0 0" xyz="-0.3 0.0 -0.075"/>
      <geometry>
        <box size="0.12 0.12 0.15"/>
      </geometry>
    </visual>
    <collision>
      <origin rpy="0 0 0" xyz="0.0 0.0 -0.075"/>
      <geometry>
        <box size="0.6 0.06 0.15"/>
      </geometry>
    </collision>
  </link>
  <gazebo reference="left_bogie_link">
    <material>Gazebo/DarkGrey</material>
  </gazebo>
  <joint name="left_bogie_pivot" type="revolute">
    <origin rpy="0 0 0" xyz="-0.3 0.0 -0.15"/>
    <parent link="left_rocker_arm"/>
    <child link="left_bogie_link"/>
    <axis xyz="0.0 3.0 0.0"/>
    <!-- Mechanical stop for the bogie (+/- 0.8 radians) -->
    <limit effort="500" lower="-0.8" upper="0.8" velocity="10"/>
    <dynamics damping="3.0" friction="1.0"/>
  </joint>
  <link name="mid_left_wheel">
    <inertial>
      <mass value="0.8"/>
      <origin rpy="1.5707 0 0" xyz="0.0 0.0 0.0"/>
      <inertia ixx="0.0013" ixy="0" ixz="0" iyy="0.0013" iyz="0" izz="0.0022"/>
    </inertial>
    <visual>
      <origin rpy="1.5707 0 0" xyz="0.0 0.0 0.0"/>
      <geometry>
        <cylinder length="0.05" radius="0.075"/>
      </geometry>
    </visual>
    <collision>
      <origin rpy="1.5707 0 0" xyz="0.0 0.0 0.0"/>
      <geometry>
        <cylinder length="0.05" radius="0.075"/>
      </geometry>
    </collision>
  </link>
  <gazebo reference="mid_left_wheel">
    <material>Gazebo/Grey</material>
    <!-- ADVANCED MECHANICS: Anisotropic Friction.
           In a 6-wheel skid steer, the wheels MUST slip sideways to turn.
           mu1 (forward friction) is high (1.2) for stair climbing grip.
           mu2 (lateral friction) is extremely low (0.1) so the robot
           can easily rotate on its center axis without fighting itself! -->
    <mu1>1.2</mu1>
    <mu2>0.1</mu2>
    <kp>1000000.0</kp>
    <kd>100.0</kd>
    <minDepth>0.001</minDepth>
  </gazebo>
  <joint name="mid_left_wheel_joint" type="continuous">
    <origin rpy="0 0 0" xyz="0.9 0.54 -0.45"/>
    <parent link="left_bogie_link"/>
    <child link="mid_left_wheel"/>
    <axis xyz="0.0 3.0 0.0"/>
    <limit effort="100" velocity="20"/>
    <dynamics damping="0.1" friction="0.1"/>
  </joint>
  <link name="back_left_wheel">
    <inertial>
      <mass value="0.8"/>
      <origin rpy="1.5707 0 0" xyz="0.0 0.0 0.0"/>
      <inertia ixx="0.0013" ixy="0" ixz="0" iyy="0.0013" iyz="0" izz="0.0022"/>
    </inertial>
    <visual>
      <origin rpy="1.5707 0 0" xyz="0.0 0.0 0.0"/>
      <geometry>
        <cylinder length="0.05" radius="0.075"/>
      </geometry>
    </visual>
    <collision>
      <origin rpy="1.5707 0 0" xyz="0.0 0.0 0.0"/>
      <geometry>
        <cylinder length="0.05" radius="0.075"/>
      </geometry>
    </collision>
  </link>
  <gazebo reference="back_left_wheel">
    <material>Gazebo/Grey</material>
    <!-- ADVANCED MECHANICS: Anisotropic Friction.
           In a 6-wheel skid steer, the wheels MUST slip sideways to turn.
           mu1 (forward friction) is high (1.2) for stair climbing grip.
           mu2 (lateral friction) is extremely low (0.1) so the robot
           can easily rotate on its center axis without fighting itself! -->
    <mu1>1.2</mu1>
    <mu2>0.1</mu2>
    <kp>1000000.0</kp>
    <kd>100.0</kd>
    <minDepth>0.001</minDepth>
  </gazebo>
  <joint name="back_left_wheel_joint" type="continuous">
    <origin rpy="0 0 0" xyz="-0.9 0.54 -0.45"/>
    <parent link="left_bogie_link"/>
    <child link="back_left_wheel"/>
    <axis xyz="0.0 3.0 0.0"/>
    <limit effort="100" velocity="20"/>
    <dynamics damping="0.1" friction="0.1"/>
  </joint>
  <!-- =============================== -->
  <!-- RIGHT SIDE ASSEMBLY             -->
  <!-- =============================== -->
  <link name="right_rocker_arm">
    <inertial>
      <mass value="0.5"/>
      <origin rpy="0 0 0" xyz="0.15 0.0 0.0"/>
      <inertia ixx="0.005" ixy="0" ixz="0" iyy="0.005" iyz="0" izz="0.005"/>
    </inertial>
    <visual>
      <origin rpy="0 0 0" xyz="0.15 0.0 0.0"/>
      <geometry>
        <box size="1.02 0.12 0.12"/>
      </geometry>
    </visual>
    <visual>
      <origin rpy="0 0 0" xyz="0.6 0.0 -0.15"/>
      <geometry>
        <box size="0.12 0.12 0.3"/>
      </geometry>
    </visual>
    <visual>
      <origin rpy="0 0 0" xyz="-0.3 0.0 -0.075"/>
      <geometry>
        <box size="0.12 0.12 0.15"/>
      </geometry>
    </visual>
    <collision>
      <origin rpy="0 0 0" xyz="0.15 0.0 -0.075"/>
      <geometry>
        <box size="0.9 0.06 0.15"/>
      </geometry>
    </collision>
  </link>
  <gazebo reference="right_rocker_arm">
    <material>Gazebo/DarkGrey</material>
  </gazebo>
  <joint name="right_differential_axle" type="revolute">
    <origin rpy="0 0 0" xyz="0.0 -0.39 0.0"/>
    <parent link="base_link"/>
    <child link="right_rocker_arm"/>
    <axis xyz="0.0 3.0 0.0"/>
    <limit effort="1000" lower="-0.6" upper="0.6" velocity="10"/>
    <dynamics damping="8.0" friction="2.0"/>
  </joint>
  <link name="front_right_wheel">
    <inertial>
      <mass value="0.8"/>
      <origin rpy="1.5707 0 0" xyz="0.0 0.0 0.0"/>
      <inertia ixx="0.0013" ixy="0" ixz="0" iyy="0.0013" iyz="0" izz="0.0022"/>
    </inertial>
    <visual>
      <origin rpy="1.5707 0 0" xyz="0.0 0.0 0.0"/>
      <geometry>
        <cylinder length="0.05" radius="0.075"/>
      </geometry>
    </visual>
    <collision>
      <origin rpy="1.5707 0 0" xyz="0.0 0.0 0.0"/>
      <geometry>
        <cylinder length="0.05" radius="0.075"/>
      </geometry>
    </collision>
  </link>
  <gazebo reference="front_right_wheel">
    <material>Gazebo/Grey</material>
    <!-- ADVANCED MECHANICS: Anisotropic Friction.
           In a 6-wheel skid steer, the wheels MUST slip sideways to turn.
           mu1 (forward friction) is high (1.2) for stair climbing grip.
           mu2 (lateral friction) is extremely low (0.1) so the robot
           can easily rotate on its center axis without fighting itself! -->
    <mu1>1.2</mu1>
    <mu2>0.1</mu2>
    <kp>1000000.0</kp>
    <kd>100.0</kd>
    <minDepth>0.001</minDepth>
  </gazebo>
  <joint name="front_right_wheel_joint" type="continuous">
    <origin rpy="0 0 0" xyz="1.8 -0.54 -0.9"/>
    <parent link="right_rocker_arm"/>
    <child link="front_right_wheel"/>
    <axis xyz="0.0 3.0 0.0"/>
    <limit effort="100" velocity="20"/>
    <dynamics damping="0.1" friction="0.1"/>
  </joint>
  <link name="right_bogie_link">
    <inertial>
      <mass value="0.5"/>
      <origin rpy="0 0 0" xyz="0.0 0.0 0.0"/>
      <inertia ixx="0.005" ixy="0" ixz="0" iyy="0.005" iyz="0" izz="0.005"/>
    </inertial>
    <visual>
      <origin rpy="0 0 0" xyz="0.0 0.0 0.0"/>
      <geometry>
        <box size="0.72 0.12 0.12"/>
      </geometry>
    </visual>
    <visual>
      <origin rpy="0 0 0" xyz="0.3 0.0 -0.075"/>
      <geometry>
        <box size="0.12 0.12 0.15"/>
      </geometry>
    </visual>
    <visual>
      <origin rpy="0 0 0" xyz="-0.3 0.0 -0.075"/>
      <geometry>
        <box size="0.12 0.12 0.15"/>
      </geometry>
    </visual>
    <collision>
      <origin rpy="0 0 0" xyz="0.0 0.0 -0.075"/>
      <geometry>
        <box size="0.6 0.06 0.15"/>
      </geometry>
    </collision>
  </link>
  <gazebo reference="right_bogie_link">
    <material>Gazebo/DarkGrey</material>
  </gazebo>
  <joint name="right_bogie_pivot" type="revolute">
    <origin rpy="0 0 0" xyz="-0.3 0.0 -0.15"/>
    <parent link="right_rocker_arm"/>
    <child link="right_bogie_link"/>
    <axis xyz="0.0 3.0 0.0"/>
    <limit effort="500" lower="-0.8" upper="0.8" velocity="10"/>
    <dynamics damping="3.0" friction="1.0"/>
  </joint>
  <link name="mid_right_wheel">
    <inertial>
      <mass value="0.8"/>
      <origin rpy="1.5707 0 0" xyz="0.0 0.0 0.0"/>
      <inertia ixx="0.0013" ixy="0" ixz="0" iyy="0.0013" iyz="0" izz="0.0022"/>
    </inertial>
    <visual>
      <origin rpy="1.5707 0 0" xyz="0.0 0.0 0.0"/>
      <geometry>
        <cylinder length="0.05" radius="0.075"/>
      </geometry>
    </visual>
    <collision>
      <origin rpy="1.5707 0 0" xyz="0.0 0.0 0.0"/>
      <geometry>
        <cylinder length="0.05" radius="0.075"/>
      </geometry>
    </collision>
  </link>
  <gazebo reference="mid_right_wheel">
    <material>Gazebo/Grey</material>
    <!-- ADVANCED MECHANICS: Anisotropic Friction.
           In a 6-wheel skid steer, the wheels MUST slip sideways to turn.
           mu1 (forward friction) is high (1.2) for stair climbing grip.
           mu2 (lateral friction) is extremely low (0.1) so the robot
           can easily rotate on its center axis without fighting itself! -->
    <mu1>1.2</mu1>
    <mu2>0.1</mu2>
    <kp>1000000.0</kp>
    <kd>100.0</kd>
    <minDepth>0.001</minDepth>
  </gazebo>
  <joint name="mid_right_wheel_joint" type="continuous">
    <origin rpy="0 0 0" xyz="0.9 -0.54 -0.45"/>
    <parent link="right_bogie_link"/>
    <child link="mid_right_wheel"/>
    <axis xyz="0.0 3.0 0.0"/>
    <limit effort="100" velocity="20"/>
    <dynamics damping="0.1" friction="0.1"/>
  </joint>
  <link name="back_right_wheel">
    <inertial>
      <mass value="0.8"/>
      <origin rpy="1.5707 0 0" xyz="0.0 0.0 0.0"/>
      <inertia ixx="0.0013" ixy="0" ixz="0" iyy="0.0013" iyz="0" izz="0.0022"/>
    </inertial>
    <visual>
      <origin rpy="1.5707 0 0" xyz="0.0 0.0 0.0"/>
      <geometry>
        <cylinder length="0.05" radius="0.075"/>
      </geometry>
    </visual>
    <collision>
      <origin rpy="1.5707 0 0" xyz="0.0 0.0 0.0"/>
      <geometry>
        <cylinder length="0.05" radius="0.075"/>
      </geometry>
    </collision>
  </link>
  <gazebo reference="back_right_wheel">
    <material>Gazebo/Grey</material>
    <!-- ADVANCED MECHANICS: Anisotropic Friction.
           In a 6-wheel skid steer, the wheels MUST slip sideways to turn.
           mu1 (forward friction) is high (1.2) for stair climbing grip.
           mu2 (lateral friction) is extremely low (0.1) so the robot
           can easily rotate on its center axis without fighting itself! -->
    <mu1>1.2</mu1>
    <mu2>0.1</mu2>
    <kp>1000000.0</kp>
    <kd>100.0</kd>
    <minDepth>0.001</minDepth>
  </gazebo>
  <joint name="back_right_wheel_joint" type="continuous">
    <origin rpy="0 0 0" xyz="-0.9 -0.54 -0.45"/>
    <parent link="right_bogie_link"/>
    <child link="back_right_wheel"/>
    <axis xyz="0.0 3.0 0.0"/>
    <limit effort="100" velocity="20"/>
    <dynamics damping="0.1" friction="0.1"/>
  </joint>
</robot>
